2025-02-04 17:23:14,630 - apscheduler.executors.default - ERROR - Job "check_pending_quizzes (trigger: interval[0:01:00], next run at: 2025-02-04 17:24:14 -03)" raised an exception
Traceback (most recent call last):
  File "/home/fom/proyectos/cuestionarios/competitions-service/env/lib/python3.12/site-packages/apscheduler/executors/base.py", line 131, in run_job
    retval = job.func(*job.args, **job.kwargs)
             ^^^^^^^^^^^^^^^^^^^^^^^^^^^^^^^^^
  File "/home/fom/proyectos/cuestionarios/competitions-service/scheduler.py", line 10, in check_pending_quizzes
    with current_app.app_context():
         ^^^^^^^^^^^^^^^^^^^^^^^
  File "/home/fom/proyectos/cuestionarios/competitions-service/env/lib/python3.12/site-packages/werkzeug/local.py", line 318, in __get__
    obj = instance._get_current_object()
          ^^^^^^^^^^^^^^^^^^^^^^^^^^^^^^
  File "/home/fom/proyectos/cuestionarios/competitions-service/env/lib/python3.12/site-packages/werkzeug/local.py", line 519, in _get_current_object
    raise RuntimeError(unbound_message) from None
RuntimeError: Working outside of application context.

This typically means that you attempted to use functionality that needed
the current application. To solve this, set up an application context
with app.app_context(). See the documentation for more information.
